<mujoco model="albert">
  <compiler angle="radian"/>
  <statistic center="0.3 0 0.4" extent="1"/>

  <visual>
    <headlight diffuse="0.6 0.6 0.6" ambient="0.3 0.3 0.3" specular="0 0 0"/>
    <rgba haze="0.15 0.25 0.35 1"/>
    <global azimuth="120" elevation="-20"/>
  </visual>

  <asset>
    <mesh name="chassis_link" file="chassis_link.STL"/>
    <texture type="skybox" builtin="gradient" rgb1="0.3 0.5 0.7" rgb2="0 0 0" width="512" height="3072"/>
    <texture type="2d" name="groundplane" builtin="checker" mark="edge" rgb1="0.2 0.3 0.4" rgb2="0.1 0.2 0.3"
      markrgb="0.8 0.8 0.8" width="300" height="300"/>
    <material name="groundplane" texture="groundplane" texuniform="true" texrepeat="5 5" reflectance="0.2"/>
  </asset>
  <worldbody>
    <light pos="0 0 1.5" dir="0 0 -1" directional="true"/>
    <geom name="floor" size="0 0 0.05" type="plane" material="groundplane"/>
    <geom type="mesh" rgba="0.8 0.8 0.9 1" mesh="chassis_link"/>
    <body name="rotacastor_right_link" pos="-0.177 -0.274 0.043">
      <inertial pos="0 0 0" mass="1" diaginertia="0.2 0.2 0.2"/>
      <joint name="rotacastor_right_joint" pos="0 0 0" axis="1 0 0" damping="1"/>
      <geom size="0.0625 0.0005" quat="0.707105 0 0.707108 0" type="cylinder" rgba="0.8 0 0 1"/>
    </body>
    <body name="rotacastor_left_link" pos="0.177 -0.274 0.043">
      <inertial pos="0 0 0" mass="1" diaginertia="0.2 0.2 0.2"/>
      <joint name="rotacastor_left_joint" pos="0 0 0" axis="1 0 0" damping="1"/>
      <geom size="0.0625 0.0005" quat="0.707105 0 0.707108 0" type="cylinder" rgba="0.8 0 0 1"/>
    </body>
    <body name="wheel_right_link" pos="-0.247 0.157 0.058">
      <inertial pos="0 0 0" mass="10" diaginertia="0.2 0.2 0.2"/>
      <joint name="wheel_right_joint" pos="0 0 0" axis="1 0 0" actuatorfrcrange="-10000 10000" damping="1"/>
      <geom size="0.08 0.0005" quat="0.707105 0 0.707108 0" type="cylinder" rgba="0.8 0 0 1"/>
    </body>
    <body name="wheel_left_link" pos="0.247 0.157 0.058">
      <inertial pos="0 0 0" mass="10" diaginertia="0.2 0.2 0.2"/>
      <joint name="wheel_left_joint" pos="0 0 0" axis="1 0 0" actuatorfrcrange="-10000 10000" damping="1"/>
      <geom size="0.08 0.0005" quat="0.707105 0 0.707108 0" type="cylinder" rgba="0.8 0 0 1"/>
    </body>
  </worldbody>
  <actuator>
    <velocity ctrllimited="true" ctrlrange="-2 2" joint="rotacastor_right_joint" kv="100"/>
    <velocity ctrllimited="true" ctrlrange="-2 2" joint="rotacastor_left_joint" kv="100"/>
    <velocity ctrllimited="true" ctrlrange="-2 2" joint="wheel_right_joint" kv="90"/>
    <velocity ctrllimited="true" ctrlrange="-2 2" joint="wheel_left_joint" kv="80"/>
  </actuator>
</mujoco>
